Workbook

Sheet Instructions
B1: IMPI EVENT QUOTATION SYSTEM
B2: How this workbook works — read this once before your first quotation
B4: THIS IS THE QUOTATION WORKBOOK
B5: This file produces your client-facing Quotation only. Postings and payroll/supplier-pay are handled in the separate ‘IMPI Posting Sheet & Pay Run’ workbook — the two are kept apart on purpose, just like your original two files, so each stays focused and simple.
B7: THE 5 TABS, IN THE ORDER YOU USE THEM
B8: 1. SETUP — your company details are already filled in. Update the CLIENT, QUOTATION and EVENT blocks for the job you are quoting.
B9: 2. RATE CARD — your client-facing price list. Each officer/post type has a Grade and a Sell Price (what you charge the client). Add to this list as needed.
B10: 3. BUILDER — this is the only place you type shift dates, times, categories and line items. Everything else is generated from here.
B11: 4. QUOTATION — your branded, client-ready quote. It builds itself automatically from Builder + Setup. Nothing to type here.
B13: STEP 1 — SETUP TAB
B14: • Fill in the CLIENT DETAILS, QUOTATION DETAILS and EVENT DETAILS blocks. The Quotation Number, VAT rate and Payment Terms can be edited here at any time — they flow through to the Quotation automatically.
B16: STEP 2 — RATE CARD TAB (your price list)
... B44: • This workbook uses standard Excel formulas only (no macros/VBA), so there is nothing to ‘enable’ and it is safe to open on any computer. The Builder tab is protected on the automatic/grey cells only — all white input cells remain fully editable.

Sheet Setup
B1: SETUP — Company, Client, Quotation & Event Details
B3: COMPANY DETAILS (fixed — IMPI RMS)
B4: Company Name | C4: IMPI RMS (Pty) Ltd
B5: Trading As
B6: Registration No. | C6: 2017/099360/07
B7: VAT Number | C7: 4120277498
B8: Address | C8: 10 Kosmos Crescent, Rynoue AH
C9: Roodeplaat, Pretoria, 0039
B10: Phone | C10: 012 543 0640
B11: Mobile (Shane Steynfaardt) | C11: 083 782 2207
B12: Email | C12: info@impi-secure.co.za
B13: Website | C13: www.impi-secure.co.za
B14: Bank | C14: Standard Bank
B15: Account Number | C15: 011059486
B16: Branch Code | C16: 010145
B18: CLIENT DETAILS (update for each new quotation)
B19: Client / Company Name
B20: Contact Person
B21: Client Email
B22: Client Phone
B23: Client VAT Number (optional)
B24: Client Registration No. (optional)
B26: QUOTATION DETAILS
B27: Quotation Number
B28: Quotation Date | C28: =TODAY()
B29: Valid Until | C29: =C28+30
B30: Reference Number / Event Name
B31: Prepared By | C31: Shane Steynfaardt
B32: Sales Person (initials) | C32: Jaco Van Dyk
B33: VAT Rate | C33: 0.15
B35: EVENT DETAILS
B36: Venue
B37: Event Date (overview)
B38: PO Number
B39: Timing (overview)
B41: PAYMENT TERMS & CONDITIONS (printed on every quotation — editable)
B42: • A minimum deposit of 50% is required no later than fourteen (14) days prior to the event date in order to confirm and secure the provision of services. • The outstanding balance shall be settled within five (5) days after the event date. • Should payment not be received within the stipulated five (5) day period, a 5% administrative fee will be applied. An additional 5% administrative fee will be levied at the end of each subsequent month for as long as the account remains outstanding.

Sheet Rate Card
B1: RATE CARD — Officer Types, Grades & Selling Prices
B2: This is your client-facing price list. Add a row per officer/post type. The Builder tab's ‘Officer Type’ dropdown pulls its list from this table, and the Grade and Sell Price fill in automatically once an Officer Type is chosen there. (Pay rates for your supplier/guards live in the separate Posting Sheet & Pay Run workbook.)
B4: Officer Type | C4: PSIRA Grade | D4: Sell Price (charged to client, per shift)
B5: Event Security Supervisor | C5: Gr B | D5: 1080
B6: Event Security Officer | C6: Gr C | D6: 870
B7: Event Reaction Officer | C7: Gr C | D7: 1350
B8: Event Safety Officer | C8: N/A | D8: 2150
B9: Event Security Supervisor - 14 Hrs | C9: Gr B | D9: 1260
B10: Event Security Officer - 14 Hrs | C10: Gr C | D10: 1015
B11: Event Reaction Officer - Men in Black | C11: Gr A | D11: 1450
B12: Event Security Manager | C12: Gr A | D12: 1550
B13: Event Cleaner Supervisor | C13: N/A | D13: 1080
B14: Event Cleaner | C14: N/A | D14: 870
B36: Pale gold cells above are placeholders — enter your real Sell Price before relying on them.

Sheet Builder
B1: BUILDER — type your shift sections and line items here | N1: SYSTEM — do not edit
B2: Add a SECTION HEADER row (Category + Date + Shift) then add LINE ITEM rows underneath it. For guard/officer lines, pick an ‘Officer Type’ from the dropdown — PSIRA Grade and Sell Price fill in automatically from the Rate Card. Type where they're posted (e.g. ‘Roaming’, ‘Main Bar Area’) into Notes and it will be added to their description on the Quotation. For non-staff lines (equipment, medics, fencing, compliance), leave Officer Type blank and fill in Description + Unit Price yourself as before. (Postings/payroll are handled in the separate Posting Sheet & Pay Run workbook — not here.) | N2: Auto-calculated columns — formulas, please leave untouched
B4: Row Type | C4: Category | D4: Date | E4: Shift | F4: Start | G4: End | H4: Qty | I4: Officer Type | J4: Description | K4: Notes / Posting Location | L4: Unit Price | M4: Shifts / Units | N4: Final Description (auto) | O4: Final Unit Price (auto) | P4: Final Grade (auto) | Q4: Amount (auto) | R4: Section Text (auto) | S4: Effective Section (auto)
N5: =IF($I5<>"",$I5&IF(OR($P5="N/A",$P5=""),""," "&$P5)&IF(T($K5)<>"",": "&$K5,""),T($J5)) | O5: =IF($I5<>"",IFERROR(INDEX(RateCard[Sell Price (charged to client, per shift)],MATCH($I5,RateCard[Officer Type],0)),0),N($L5)) | P5: =IF($I5<>"",IFERROR(INDEX(RateCard[PSIRA Grade],MATCH($I5,RateCard[Officer Type],0)),"N/A"),"N/A") | Q5: =IF($B5="LINE ITEM",N($H5)*N($O5)*N($M5),"") | R5: =IF($B5="SECTION HEADER",$C5&": "&TEXT($D5,"dddd d mmmm yyyy")&" - "&$E5&" ("&TEXT($F5,"hh""h""mm")&" - "&TEXT($G5,"hh""h""mm")&")","") | S5: =IF($B5="SECTION HEADER",$R5,"")
N6: =IF($I6<>"",$I6&IF(OR($P6="N/A",$P6=""),""," "&$P6)&IF(T($K6)<>"",": "&$K6,""),T($J6)) | O6: =IF($I6<>"",IFERROR(INDEX(RateCard[Sell Price (charged to client, per shift)],MATCH($I6,RateCard[Officer Type],0)),0),N($L6)) | P6: =IF($I6<>"",IFERROR(INDEX(RateCard[PSIRA Grade],MATCH($I6,RateCard[Officer Type],0)),"N/A"),"N/A") | Q6: =IF($B6="LINE ITEM",N($H6)*N($O6)*N($M6),"") | R6: =IF($B6="SECTION HEADER",$C6&": "&TEXT($D6,"dddd d mmmm yyyy")&" - "&$E6&" ("&TEXT($F6,"hh""h""mm")&" - "&TEXT($G6,"hh""h""mm")&")","") | S6: =IF($B6="SECTION HEADER",$R6,S5)
N7: =IF($I7<>"",$I7&IF(OR($P7="N/A",$P7=""),""," "&$P7)&IF(T($K7)<>"",": "&$K7,""),T($J7)) | O7: =IF($I7<>"",IFERROR(INDEX(RateCard[Sell Price (charged to client, per shift)],MATCH($I7,RateCard[Officer Type],0)),0),N($L7)) | P7: =IF($I7<>"",IFERROR(INDEX(RateCard[PSIRA Grade],MATCH($I7,RateCard[Officer Type],0)),"N/A"),"N/A") | Q7: =IF($B7="LINE ITEM",N($H7)*N($O7)*N($M7),"") | R7: =IF($B7="SECTION HEADER",$C7&": "&TEXT($D7,"dddd d mmmm yyyy")&" - "&$E7&" ("&TEXT($F7,"hh""h""mm")&" - "&TEXT($G7,"hh""h""mm")&")","") | S7: =IF($B7="SECTION HEADER",$R7,S6)
N8: =IF($I8<>"",$I8&IF(OR($P8="N/A",$P8=""),""," "&$P8)&IF(T($K8)<>"",": "&$K8,""),T($J8)) | O8: =IF($I8<>"",IFERROR(INDEX(RateCard[Sell Price (charged to client, per shift)],MATCH($I8,RateCard[Officer Type],0)),0),N($L8)) | P8: =IF($I8<>"",IFERROR(INDEX(RateCard[PSIRA Grade],MATCH($I8,RateCard[Officer Type],0)),"N/A"),"N/A") | Q8: =IF($B8="LINE ITEM",N($H8)*N($O8)*N($M8),"") | R8: =IF($B8="SECTION HEADER",$C8&": "&TEXT($D8,"dddd d mmmm yyyy")&" - "&$E8&" ("&TEXT($F8,"hh""h""mm")&" - "&TEXT($G8,"hh""h""mm")&")","") | S8: =IF($B8="SECTION HEADER",$R8,S7)
N9: =IF($I9<>"",$I9&IF(OR($P9="N/A",$P9=""),""," "&$P9)&IF(T($K9)<>"",": "&$K9,""),T($J9)) | O9: =IF($I9<>"",IFERROR(INDEX(RateCard[Sell Price (charged to client, per shift)],MATCH($I9,RateCard[Officer Type],0)),0),N($L9)) | P9: =IF($I9<>"",IFERROR(INDEX(RateCard[PSIRA Grade],MATCH($I9,RateCard[Officer Type],0)),"N/A"),"N/A") | Q9: =IF($B9="LINE ITEM",N($H9)*N($O9)*N($M9),"") | R9: =IF($B9="SECTION HEADER",$C9&": "&TEXT($D9,"dddd d mmmm yyyy")&" - "&$E9&" ("&TEXT($F9,"hh""h""mm")&" - "&TEXT($G9,"hh""h""mm")&")","") | S9: =IF($B9="SECTION HEADER",$R9,S8)
N10: =IF($I10<>"",$I10&IF(OR($P10="N/A",$P10=""),""," "&$P10)&IF(T($K10)<>"",": "&$K10,""),T($J10)) | O10: =IF($I10<>"",IFERROR(INDEX(RateCard[Sell Price (charged to client, per shift)],MATCH($I10,RateCard[Officer Type],0)),0),N($L10)) | P10: =IF($I10<>"",IFERROR(INDEX(RateCard[PSIRA Grade],MATCH($I10,RateCard[Officer Type],0)),"N/A"),"N/A") | Q10: =IF($B10="LINE ITEM",N($H10)*N($O10)*N($M10),"") | R10: =IF($B10="SECTION HEADER",$C10&": "&TEXT($D10,"dddd d mmmm yyyy")&" - "&$E10&" ("&TEXT($F10,"hh""h""mm")&" - "&TEXT($G10,"hh""h""mm")&")","") | S10: =IF($B10="SECTION HEADER",$R10,S9)
N11: =IF($I11<>"",$I11&IF(OR($P11="N/A",$P11=""),""," "&$P11)&IF(T($K11)<>"",": "&$K11,""),T($J11)) | O11: =IF($I11<>"",IFERROR(INDEX(RateCard[Sell Price (charged to client, per shift)],MATCH($I11,RateCard[Officer Type],0)),0),N($L11)) | P11: =IF($I11<>"",IFERROR(INDEX(RateCard[PSIRA Grade],MATCH($I11,RateCard[Officer Type],0)),"N/A"),"N/A") | Q11: =IF($B11="LINE ITEM",N($H11)*N($O11)*N($M11),"") | R11: =IF($B11="SECTION HEADER",$C11&": "&TEXT($D11,"dddd d mmmm yyyy")&" - "&$E11&" ("&TEXT($F11,"hh""h""mm")&" - "&TEXT($G11,"hh""h""mm")&")","") | S11: =IF($B11="SECTION HEADER",$R11,S10)
N12: =IF($I12<>"",$I12&IF(OR($P12="N/A",$P12=""),""," "&$P12)&IF(T($K12)<>"",": "&$K12,""),T($J12)) | O12: =IF($I12<>"",IFERROR(INDEX(RateCard[Sell Price (charged to client, per shift)],MATCH($I12,RateCard[Officer Type],0)),0),N($L12)) | P12: =IF($I12<>"",IFERROR(INDEX(RateCard[PSIRA Grade],MATCH($I12,RateCard[Officer Type],0)),"N/A"),"N/A") | Q12: =IF($B12="LINE ITEM",N($H12)*N($O12)*N($M12),"") | R12: =IF($B12="SECTION HEADER",$C12&": "&TEXT($D12,"dddd d mmmm yyyy")&" - "&$E12&" ("&TEXT($F12,"hh""h""mm")&" - "&TEXT($G12,"hh""h""mm")&")","") | S12: =IF($B12="SECTION HEADER",$R12,S11)
N13: =IF($I13<>"",$I13&IF(OR($P13="N/A",$P13=""),""," "&$P13)&IF(T($K13)<>"",": "&$K13,""),T($J13)) | O13: =IF($I13<>"",IFERROR(INDEX(RateCard[Sell Price (charged to client, per shift)],MATCH($I13,RateCard[Officer Type],0)),0),N($L13)) | P13: =IF($I13<>"",IFERROR(INDEX(RateCard[PSIRA Grade],MATCH($I13,RateCard[Officer Type],0)),"N/A"),"N/A") | Q13: =IF($B13="LINE ITEM",N($H13)*N($O13)*N($M13),"") | R13: =IF($B13="SECTION HEADER",$C13&": "&TEXT($D13,"dddd d mmmm yyyy")&" - "&$E13&" ("&TEXT($F13,"hh""h""mm")&" - "&TEXT($G13,"hh""h""mm")&")","") | S13: =IF($B13="SECTION HEADER",$R13,S12)
N14: =IF($I14<>"",$I14&IF(OR($P14="N/A",$P14=""),""," "&$P14)&IF(T($K14)<>"",": "&$K14,""),T($J14)) | O14: =IF($I14<>"",IFERROR(INDEX(RateCard[Sell Price (charged to client, per shift)],MATCH($I14,RateCard[Officer Type],0)),0),N($L14)) | P14: =IF($I14<>"",IFERROR(INDEX(RateCard[PSIRA Grade],MATCH($I14,RateCard[Officer Type],0)),"N/A"),"N/A") | Q14: =IF($B14="LINE ITEM",N($H14)*N($O14)*N($M14),"") | R14: =IF($B14="SECTION HEADER",$C14&": "&TEXT($D14,"dddd d mmmm yyyy")&" - "&$E14&" ("&TEXT($F14,"hh""h""mm")&" - "&TEXT($G14,"hh""h""mm")&")","") | S14: =IF($B14="SECTION HEADER",$R14,S13)
N15: =IF($I15<>"",$I15&IF(OR($P15="N/A",$P15=""),""," "&$P15)&IF(T($K15)<>"",": "&$K15,""),T($J15)) | O15: =IF($I15<>"",IFERROR(INDEX(RateCard[Sell Price (charged to client, per shift)],MATCH($I15,RateCard[Officer Type],0)),0),N($L15)) | P15: =IF($I15<>"",IFERROR(INDEX(RateCard[PSIRA Grade],MATCH($I15,RateCard[Officer Type],0)),"N/A"),"N/A") | Q15: =IF($B15="LINE ITEM",N($H15)*N($O15)*N($M15),"") | R15: =IF($B15="SECTION HEADER",$C15&": "&TEXT($D15,"dddd d mmmm yyyy")&" - "&$E15&" ("&TEXT($F15,"hh""h""mm")&" - "&TEXT($G15,"hh""h""mm")&")","") | S15: =IF($B15="SECTION HEADER",$R15,S14)
N16: =IF($I16<>"",$I16&IF(OR($P16="N/A",$P16=""),""," "&$P16)&IF(T($K16)<>"",": "&$K16,""),T($J16)) | O16: =IF($I16<>"",IFERROR(INDEX(RateCard[Sell Price (charged to client, per shift)],MATCH($I16,RateCard[Officer Type],0)),0),N($L16)) | P16: =IF($I16<>"",IFERROR(INDEX(RateCard[PSIRA Grade],MATCH($I16,RateCard[Officer Type],0)),"N/A"),"N/A") | Q16: =IF($B16="LINE ITEM",N($H16)*N($O16)*N($M16),"") | R16: =IF($B16="SECTION HEADER",$C16&": "&TEXT($D16,"dddd d mmmm yyyy")&" - "&$E16&" ("&TEXT($F16,"hh""h""mm")&" - "&TEXT($G16,"hh""h""mm")&")","") | S16: =IF($B16="SECTION HEADER",$R16,S15)
N17: =IF($I17<>"",$I17&IF(OR($P17="N/A",$P17=""),""," "&$P17)&IF(T($K17)<>"",": "&$K17,""),T($J17)) | O17: =IF($I17<>"",IFERROR(INDEX(RateCard[Sell Price (charged to client, per shift)],MATCH($I17,RateCard[Officer Type],0)),0),N($L17)) | P17: =IF($I17<>"",IFERROR(INDEX(RateCard[PSIRA Grade],MATCH($I17,RateCard[Officer Type],0)),"N/A"),"N/A") | Q17: =IF($B17="LINE ITEM",N($H17)*N($O17)*N($M17),"") | R17: =IF($B17="SECTION HEADER",$C17&": "&TEXT($D17,"dddd d mmmm yyyy")&" - "&$E17&" ("&TEXT($F17,"hh""h""mm")&" - "&TEXT($G17,"hh""h""mm")&")","") | S17: =IF($B17="SECTION HEADER",$R17,S16)
... N154: =IF($I154<>"",$I154&IF(OR($P154="N/A",$P154=""),""," "&$P154)&IF(T($K154)<>"",": "&$K154,""),T($J154)) | O154: =IF($I154<>"",IFERROR(INDEX(RateCard[Sell Price (charged to client, per shift)],MATCH($I154,RateCard[Officer Type],0)),0),N($L154)) | P154: =IF($I154<>"",IFERROR(INDEX(RateCard[PSIRA Grade],MATCH($I154,RateCard[Officer Type],0)),"N/A"),"N/A") | Q154: =IF($B154="LINE ITEM",N($H154)*N($O154)*N($M154),"") | R154: =IF($B154="SECTION HEADER",$C154&": "&TEXT($D154,"dddd d mmmm yyyy")&" - "&$E154&" ("&TEXT($F154,"hh""h""mm")&" - "&TEXT($G154,"hh""h""mm")&")","") | S154: =IF($B154="SECTION HEADER",$R154,S153)

Sheet Quotation
E3: QUOTATION
E4: Quotation No # | G4: =Setup!C27
E5: Quotation Date | G5: =Setup!C28
E6: Valid Until | G6: =Setup!C29
E7: Reference | G7: =Setup!C30
B11: QUOTATION FROM | D11: QUOTATION FOR
B12: =Setup!C4 | D12: =Setup!C19
B13: =Setup!C8 | D13: ="Contact: "&Setup!C20
B14: =Setup!C9 | D14: ="Email: "&Setup!C21
B15: ="Reg No: "&Setup!C6 | D15: ="Phone: "&Setup!C22
B16: ="VAT No: "&Setup!C7
B17: ="Email: "&Setup!C12
B18: ="Phone: "&Setup!C10
B20: Sales Person | D20: Venue | E20: Event Date | F20: PO Number | G20: Timing
B21: =Setup!C32 | D21: =Setup!C36 | E21: =Setup!C37 | F21: =Setup!C38 | G21: =Setup!C39
B23: QTY | C23: DESCRIPTION | D23: NOTES | E23: UNIT PRICE | F23: SHIFTS | G23: AMOUNT
B24: =IF(J24="LINE ITEM",IFERROR(INDEX(Builder[Qty],I24),""),"") | C24: =IF(J24="SECTION HEADER",INDEX(Builder[Section Text (auto)],I24),IF(J24="LINE ITEM","x "&T(INDEX(Builder[Final Description (auto)],I24)),"")) | D24: =IF(J24="LINE ITEM",IF(T(INDEX(Builder[Officer Type],I24))<>"","",T(INDEX(Builder[Notes / Posting Location],I24))),"") | E24: =IF(J24="LINE ITEM",IFERROR(INDEX(Builder[Final Unit Price (auto)],I24),""),"") | F24: =IF(J24="LINE ITEM",IFERROR(INDEX(Builder[Shifts / Units],I24),""),"") | G24: =IF(J24="LINE ITEM",IFERROR(INDEX(Builder[Amount (auto)],I24),""),"") | I24: =ROW()-23 | J24: =INDEX(Builder[Row Type],I24)
B25: =IF(J25="LINE ITEM",IFERROR(INDEX(Builder[Qty],I25),""),"") | C25: =IF(J25="SECTION HEADER",INDEX(Builder[Section Text (auto)],I25),IF(J25="LINE ITEM","x "&T(INDEX(Builder[Final Description (auto)],I25)),"")) | D25: =IF(J25="LINE ITEM",IF(T(INDEX(Builder[Officer Type],I25))<>"","",T(INDEX(Builder[Notes / Posting Location],I25))),"") | E25: =IF(J25="LINE ITEM",IFERROR(INDEX(Builder[Final Unit Price (auto)],I25),""),"") | F25: =IF(J25="LINE ITEM",IFERROR(INDEX(Builder[Shifts / Units],I25),""),"") | G25: =IF(J25="LINE ITEM",IFERROR(INDEX(Builder[Amount (auto)],I25),""),"") | I25: =ROW()-23 | J25: =INDEX(Builder[Row Type],I25)
B26: =IF(J26="LINE ITEM",IFERROR(INDEX(Builder[Qty],I26),""),"") | C26: =IF(J26="SECTION HEADER",INDEX(Builder[Section Text (auto)],I26),IF(J26="LINE ITEM","x "&T(INDEX(Builder[Final Description (auto)],I26)),"")) | D26: =IF(J26="LINE ITEM",IF(T(INDEX(Builder[Officer Type],I26))<>"","",T(INDEX(Builder[Notes / Posting Location],I26))),"") | E26: =IF(J26="LINE ITEM",IFERROR(INDEX(Builder[Final Unit Price (auto)],I26),""),"") | F26: =IF(J26="LINE ITEM",IFERROR(INDEX(Builder[Shifts / Units],I26),""),"") | G26: =IF(J26="LINE ITEM",IFERROR(INDEX(Builder[Amount (auto)],I26),""),"") | I26: =ROW()-23 | J26: =INDEX(Builder[Row Type],I26)
B27: =IF(J27="LINE ITEM",IFERROR(INDEX(Builder[Qty],I27),""),"") | C27: =IF(J27="SECTION HEADER",INDEX(Builder[Section Text (auto)],I27),IF(J27="LINE ITEM","x "&T(INDEX(Builder[Final Description (auto)],I27)),"")) | D27: =IF(J27="LINE ITEM",IF(T(INDEX(Builder[Officer Type],I27))<>"","",T(INDEX(Builder[Notes / Posting Location],I27))),"") | E27: =IF(J27="LINE ITEM",IFERROR(INDEX(Builder[Final Unit Price (auto)],I27),""),"") | F27: =IF(J27="LINE ITEM",IFERROR(INDEX(Builder[Shifts / Units],I27),""),"") | G27: =IF(J27="LINE ITEM",IFERROR(INDEX(Builder[Amount (auto)],I27),""),"") | I27: =ROW()-23 | J27: =INDEX(Builder[Row Type],I27)
B28: =IF(J28="LINE ITEM",IFERROR(INDEX(Builder[Qty],I28),""),"") | C28: =IF(J28="SECTION HEADER",INDEX(Builder[Section Text (auto)],I28),IF(J28="LINE ITEM","x "&T(INDEX(Builder[Final Description (auto)],I28)),"")) | D28: =IF(J28="LINE ITEM",IF(T(INDEX(Builder[Officer Type],I28))<>"","",T(INDEX(Builder[Notes / Posting Location],I28))),"") | E28: =IF(J28="LINE ITEM",IFERROR(INDEX(Builder[Final Unit Price (auto)],I28),""),"") | F28: =IF(J28="LINE ITEM",IFERROR(INDEX(Builder[Shifts / Units],I28),""),"") | G28: =IF(J28="LINE ITEM",IFERROR(INDEX(Builder[Amount (auto)],I28),""),"") | I28: =ROW()-23 | J28: =INDEX(Builder[Row Type],I28)
B29: =IF(J29="LINE ITEM",IFERROR(INDEX(Builder[Qty],I29),""),"") | C29: =IF(J29="SECTION HEADER",INDEX(Builder[Section Text (auto)],I29),IF(J29="LINE ITEM","x "&T(INDEX(Builder[Final Description (auto)],I29)),"")) | D29: =IF(J29="LINE ITEM",IF(T(INDEX(Builder[Officer Type],I29))<>"","",T(INDEX(Builder[Notes / Posting Location],I29))),"") | E29: =IF(J29="LINE ITEM",IFERROR(INDEX(Builder[Final Unit Price (auto)],I29),""),"") | F29: =IF(J29="LINE ITEM",IFERROR(INDEX(Builder[Shifts / Units],I29),""),"") | G29: =IF(J29="LINE ITEM",IFERROR(INDEX(Builder[Amount (auto)],I29),""),"") | I29: =ROW()-23 | J29: =INDEX(Builder[Row Type],I29)
C30: =IF(J30="SECTION HEADER",INDEX(Builder[Section Text (auto)],I30),IF(J30="LINE ITEM","x "&T(INDEX(Builder[Final Description (auto)],I30)),"")) | D30: =IF(J30="LINE ITEM",IF(T(INDEX(Builder[Officer Type],I30))<>"","",T(INDEX(Builder[Notes / Posting Location],I30))),"") | E30: =IF(J30="LINE ITEM",IFERROR(INDEX(Builder[Final Unit Price (auto)],I30),""),"") | F30: =IF(J30="LINE ITEM",IFERROR(INDEX(Builder[Shifts / Units],I30),""),"") | G30: =IF(J30="LINE ITEM",IFERROR(INDEX(Builder[Amount (auto)],I30),""),"") | I30: =ROW()-23 | J30: =INDEX(Builder[Row Type],I30)
B31: =IF(J31="LINE ITEM",IFERROR(INDEX(Builder[Qty],I31),""),"") | C31: =IF(J31="SECTION HEADER",INDEX(Builder[Section Text (auto)],I31),IF(J31="LINE ITEM","x "&T(INDEX(Builder[Final Description (auto)],I31)),"")) | D31: =IF(J31="LINE ITEM",IF(T(INDEX(Builder[Officer Type],I31))<>"","",T(INDEX(Builder[Notes / Posting Location],I31))),"") | E31: =IF(J31="LINE ITEM",IFERROR(INDEX(Builder[Final Unit Price (auto)],I31),""),"") | F31: =IF(J31="LINE ITEM",IFERROR(INDEX(Builder[Shifts / Units],I31),""),"") | G31: =IF(J31="LINE ITEM",IFERROR(INDEX(Builder[Amount (auto)],I31),""),"") | I31: =ROW()-23 | J31: =INDEX(Builder[Row Type],I31)
B32: =IF(J32="LINE ITEM",IFERROR(INDEX(Builder[Qty],I32),""),"") | C32: =IF(J32="SECTION HEADER",INDEX(Builder[Section Text (auto)],I32),IF(J32="LINE ITEM","x "&T(INDEX(Builder[Final Description (auto)],I32)),"")) | D32: =IF(J32="LINE ITEM",IF(T(INDEX(Builder[Officer Type],I32))<>"","",T(INDEX(Builder[Notes / Posting Location],I32))),"") | E32: =IF(J32="LINE ITEM",IFERROR(INDEX(Builder[Final Unit Price (auto)],I32),""),"") | F32: =IF(J32="LINE ITEM",IFERROR(INDEX(Builder[Shifts / Units],I32),""),"") | G32: =IF(J32="LINE ITEM",IFERROR(INDEX(Builder[Amount (auto)],I32),""),"") | I32: =ROW()-23 | J32: =INDEX(Builder[Row Type],I32)
B33: =IF(J33="LINE ITEM",IFERROR(INDEX(Builder[Qty],I33),""),"") | C33: =IF(J33="SECTION HEADER",INDEX(Builder[Section Text (auto)],I33),IF(J33="LINE ITEM","x "&T(INDEX(Builder[Final Description (auto)],I33)),"")) | D33: =IF(J33="LINE ITEM",IF(T(INDEX(Builder[Officer Type],I33))<>"","",T(INDEX(Builder[Notes / Posting Location],I33))),"") | E33: =IF(J33="LINE ITEM",IFERROR(INDEX(Builder[Final Unit Price (auto)],I33),""),"") | F33: =IF(J33="LINE ITEM",IFERROR(INDEX(Builder[Shifts / Units],I33),""),"") | G33: =IF(J33="LINE ITEM",IFERROR(INDEX(Builder[Amount (auto)],I33),""),"") | I33: =ROW()-23 | J33: =INDEX(Builder[Row Type],I33)
B34: =IF(J34="LINE ITEM",IFERROR(INDEX(Builder[Qty],I34),""),"") | C34: =IF(J34="SECTION HEADER",INDEX(Builder[Section Text (auto)],I34),IF(J34="LINE ITEM","x "&T(INDEX(Builder[Final Description (auto)],I34)),"")) | D34: =IF(J34="LINE ITEM",IF(T(INDEX(Builder[Officer Type],I34))<>"","",T(INDEX(Builder[Notes / Posting Location],I34))),"") | E34: =IF(J34="LINE ITEM",IFERROR(INDEX(Builder[Final Unit Price (auto)],I34),""),"") | F34: =IF(J34="LINE ITEM",IFERROR(INDEX(Builder[Shifts / Units],I34),""),"") | G34: =IF(J34="LINE ITEM",IFERROR(INDEX(Builder[Amount (auto)],I34),""),"") | I34: =ROW()-23 | J34: =INDEX(Builder[Row Type],I34)
B35: =IF(J35="LINE ITEM",IFERROR(INDEX(Builder[Qty],I35),""),"") | C35: =IF(J35="SECTION HEADER",INDEX(Builder[Section Text (auto)],I35),IF(J35="LINE ITEM","x "&T(INDEX(Builder[Final Description (auto)],I35)),"")) | D35: =IF(J35="LINE ITEM",IF(T(INDEX(Builder[Officer Type],I35))<>"","",T(INDEX(Builder[Notes / Posting Location],I35))),"") | E35: =IF(J35="LINE ITEM",IFERROR(INDEX(Builder[Final Unit Price (auto)],I35),""),"") | F35: =IF(J35="LINE ITEM",IFERROR(INDEX(Builder[Shifts / Units],I35),""),"") | G35: =IF(J35="LINE ITEM",IFERROR(INDEX(Builder[Amount (auto)],I35),""),"") | I35: =ROW()-23 | J35: =INDEX(Builder[Row Type],I35)
B36: =IF(J36="LINE ITEM",IFERROR(INDEX(Builder[Qty],I36),""),"") | C36: =IF(J36="SECTION HEADER",INDEX(Builder[Section Text (auto)],I36),IF(J36="LINE ITEM","x "&T(INDEX(Builder[Final Description (auto)],I36)),"")) | D36: =IF(J36="LINE ITEM",IF(T(INDEX(Builder[Officer Type],I36))<>"","",T(INDEX(Builder[Notes / Posting Location],I36))),"") | E36: =IF(J36="LINE ITEM",IFERROR(INDEX(Builder[Final Unit Price (auto)],I36),""),"") | F36: =IF(J36="LINE ITEM",IFERROR(INDEX(Builder[Shifts / Units],I36),""),"") | G36: =IF(J36="LINE ITEM",IFERROR(INDEX(Builder[Amount (auto)],I36),""),"") | I36: =ROW()-23 | J36: =INDEX(Builder[Row Type],I36)
B37: =IF(J37="LINE ITEM",IFERROR(INDEX(Builder[Qty],I37),""),"") | C37: =IF(J37="SECTION HEADER",INDEX(Builder[Section Text (auto)],I37),IF(J37="LINE ITEM","x "&T(INDEX(Builder[Final Description (auto)],I37)),"")) | D37: =IF(J37="LINE ITEM",IF(T(INDEX(Builder[Officer Type],I37))<>"","",T(INDEX(Builder[Notes / Posting Location],I37))),"") | E37: =IF(J37="LINE ITEM",IFERROR(INDEX(Builder[Final Unit Price (auto)],I37),""),"") | F37: =IF(J37="LINE ITEM",IFERROR(INDEX(Builder[Shifts / Units],I37),""),"") | G37: =IF(J37="LINE ITEM",IFERROR(INDEX(Builder[Amount (auto)],I37),""),"") | I37: =ROW()-23 | J37: =INDEX(Builder[Row Type],I37)
B38: =IF(J38="LINE ITEM",IFERROR(INDEX(Builder[Qty],I38),""),"") | C38: =IF(J38="SECTION HEADER",INDEX(Builder[Section Text (auto)],I38),IF(J38="LINE ITEM","x "&T(INDEX(Builder[Final Description (auto)],I38)),"")) | D38: =IF(J38="LINE ITEM",IF(T(INDEX(Builder[Officer Type],I38))<>"","",T(INDEX(Builder[Notes / Posting Location],I38))),"") | E38: =IF(J38="LINE ITEM",IFERROR(INDEX(Builder[Final Unit Price (auto)],I38),""),"") | F38: =IF(J38="LINE ITEM",IFERROR(INDEX(Builder[Shifts / Units],I38),""),"") | G38: =IF(J38="LINE ITEM",IFERROR(INDEX(Builder[Amount (auto)],I38),""),"") | I38: =ROW()-23 | J38: =INDEX(Builder[Row Type],I38)
B39: =IF(J39="LINE ITEM",IFERROR(INDEX(Builder[Qty],I39),""),"") | C39: =IF(J39="SECTION HEADER",INDEX(Builder[Section Text (auto)],I39),IF(J39="LINE ITEM","x "&T(INDEX(Builder[Final Description (auto)],I39)),"")) | D39: =IF(J39="LINE ITEM",IF(T(INDEX(Builder[Officer Type],I39))<>"","",T(INDEX(Builder[Notes / Posting Location],I39))),"") | E39: =IF(J39="LINE ITEM",IFERROR(INDEX(Builder[Final Unit Price (auto)],I39),""),"") | F39: =IF(J39="LINE ITEM",IFERROR(INDEX(Builder[Shifts / Units],I39),""),"") | G39: =IF(J39="LINE ITEM",IFERROR(INDEX(Builder[Amount (auto)],I39),""),"") | I39: =ROW()-23 | J39: =INDEX(Builder[Row Type],I39)
B40: =IF(J40="LINE ITEM",IFERROR(INDEX(Builder[Qty],I40),""),"") | C40: =IF(J40="SECTION HEADER",INDEX(Builder[Section Text (auto)],I40),IF(J40="LINE ITEM","x "&T(INDEX(Builder[Final Description (auto)],I40)),"")) | D40: =IF(J40="LINE ITEM",IF(T(INDEX(Builder[Officer Type],I40))<>"","",T(INDEX(Builder[Notes / Posting Location],I40))),"") | E40: =IF(J40="LINE ITEM",IFERROR(INDEX(Builder[Final Unit Price (auto)],I40),""),"") | F40: =IF(J40="LINE ITEM",IFERROR(INDEX(Builder[Shifts / Units],I40),""),"") | G40: =IF(J40="LINE ITEM",IFERROR(INDEX(Builder[Amount (auto)],I40),""),"") | I40: =ROW()-23 | J40: =INDEX(Builder[Row Type],I40)
B41: =IF(J41="LINE ITEM",IFERROR(INDEX(Builder[Qty],I41),""),"") | C41: =IF(J41="SECTION HEADER",INDEX(Builder[Section Text (auto)],I41),IF(J41="LINE ITEM","x "&T(INDEX(Builder[Final Description (auto)],I41)),"")) | D41: =IF(J41="LINE ITEM",IF(T(INDEX(Builder[Officer Type],I41))<>"","",T(INDEX(Builder[Notes / Posting Location],I41))),"") | E41: =IF(J41="LINE ITEM",IFERROR(INDEX(Builder[Final Unit Price (auto)],I41),""),"") | F41: =IF(J41="LINE ITEM",IFERROR(INDEX(Builder[Shifts / Units],I41),""),"") | G41: =IF(J41="LINE ITEM",IFERROR(INDEX(Builder[Amount (auto)],I41),""),"") | I41: =ROW()-23 | J41: =INDEX(Builder[Row Type],I41)
B42: =IF(J42="LINE ITEM",IFERROR(INDEX(Builder[Qty],I42),""),"") | C42: =IF(J42="SECTION HEADER",INDEX(Builder[Section Text (auto)],I42),IF(J42="LINE ITEM","x "&T(INDEX(Builder[Final Description (auto)],I42)),"")) | D42: =IF(J42="LINE ITEM",IF(T(INDEX(Builder[Officer Type],I42))<>"","",T(INDEX(Builder[Notes / Posting Location],I42))),"") | E42: =IF(J42="LINE ITEM",IFERROR(INDEX(Builder[Final Unit Price (auto)],I42),""),"") | F42: =IF(J42="LINE ITEM",IFERROR(INDEX(Builder[Shifts / Units],I42),""),"") | G42: =IF(J42="LINE ITEM",IFERROR(INDEX(Builder[Amount (auto)],I42),""),"") | I42: =ROW()-23 | J42: =INDEX(Builder[Row Type],I42)
... B173: =IF(J173="LINE ITEM",IFERROR(INDEX(Builder[Qty],I173),""),"") | C173: =IF(J173="SECTION HEADER",INDEX(Builder[Section Text (auto)],I173),IF(J173="LINE ITEM","x "&T(INDEX(Builder[Final Description (auto)],I173)),"")) | D173: =IF(J173="LINE ITEM",IF(T(INDEX(Builder[Officer Type],I173))<>"","",T(INDEX(Builder[Notes / Posting Location],I173))),"") | E173: =IF(J173="LINE ITEM",IFERROR(INDEX(Builder[Final Unit Price (auto)],I173),""),"") | F173: =IF(J173="LINE ITEM",IFERROR(INDEX(Builder[Shifts / Units],I173),""),"") | G173: =IF(J173="LINE ITEM",IFERROR(INDEX(Builder[Amount (auto)],I173),""),"") | I173: =ROW()-23 | J173: =INDEX(Builder[Row Type],I173)
B175: {=IF((SUMPRODUCT(MAX((J24:J173<>"")*ROW(J24:J173))))=0,"","Tip: your last line of data is around row "&(SUMPRODUCT(MAX((J24:J173<>"")*ROW(J24:J173))))&" — select any fully blank rows below that and Hide Rows before exporting to PDF.")}
B176: BANKING DETAILS | F176: SUBTOTAL | G176: =SUM(G24:G173)
B177: ="Bank: "&Setup!C14 | F177: ="VAT @ "&TEXT(Setup!C33,"0%") | G177: =G176*Setup!C33
B178: ="Account No: "&Setup!C15 | F178: TOTAL DUE | G178: =G176+G177
...
